Workbook

Sheet Pricing
A1: List Barang | B1: Qty | C1: Harga | E1: Isi | F1: Note | H1: Satuan Jual | J1: Harga Pokok | K1: MU | L1: Harga Jual | M1: Harga Jual Shopee Bali | N1: Margin | O1: Subtotal
A2: Cup Plastik | K2: 1.2
A3: Starindo 12 | B3: dus | C3: Rp | D3: 427000 | E3: 2000 | H3: =E3/50 -> 40 | I3: Slop | J3: =D3/H3 -> 10675 | K3: =J3*$K$2 -> 12810 | L3: 11000 | M3: 14500 | N3: =L3-J3 -> 325 | O3: =H3*N3 -> 13000
A4: Starindo 14 | B4: dus | C4: Rp | D4: 427000 | E4: 2000 | H4: =E4/50 -> 40 | I4: Slop | J4: =D4/H4 -> 10675 | K4: =J4*$K$2 -> 12810 | L4: 11000 | M4: 14500 | N4: =L4-J4 -> 325 | O4: =H4*N4 -> 13000
A5: Starindo 16 | B5: dus | C5: Rp | D5: 427000 | E5: 2000 | H5: =E5/50 -> 40 | I5: Slop | J5: =D5/H5 -> 10675 | K5: =J5*$K$2 -> 12810 | L5: 11000 | M5: 14500 | N5: =L5-J5 -> 325 | O5: =H5*N5 -> 13000
A6: Hok 12 | B6: dus | C6: Rp | D6: 345000 | E6: 2000 | H6: =E6/50 -> 40 | I6: Slop | J6: =D6/H6 -> 8625 | K6: =J6*$K$2 -> 10350 | L6: 11000 | M6: 10000 | N6: =L6-J6 -> 2375 | O6: =H6*N6 -> 95000
A7: Hok 14 | B7: dus | C7: Rp | D7: 345000 | E7: 2000 | H7: =E7/50 -> 40 | I7: Slop | J7: =D7/H7 -> 8625 | K7: =J7*$K$2 -> 10350 | L7: 11000 | M7: 10000 | N7: =L7-J7 -> 2375 | O7: =H7*N7 -> 95000
A8: Hok 16 | B8: dus | C8: Rp | D8: 350000 | E8: 2000 | H8: =E8/50 -> 40 | I8: Slop | J8: =D8/H8 -> 8750 | K8: =J8*$K$2 -> 10500 | L8: 11000 | M8: 9000 | N8: =L8-J8 -> 2250 | O8: =H8*N8 -> 90000
A9: Hok 18 | B9: dus | C9: Rp | D9: 318000 | E9: 2000 | H9: =E9/50 -> 40 | I9: Slop | J9: =D9/H9 -> 7950 | K9: =J9*$K$2 -> 9540 | L9: 11000 | N9: =L9-J9 -> 3050 | O9: =H9*N9 -> 122000
A10: Hok 22 | B10: dus | C10: Rp | D10: 384000 | E10: 2000 | H10: =E10/50 -> 40 | I10: Slop | J10: =D10/H10 -> 9600 | K10: =J10*$K$2 -> 11520 | L10: 0 | N10: =L10-J10 -> -9600 | O10: =H10*N10 -> -384000
A11: Cup Euro motif | B11: dus | C11: Rp | D11: 288000 | E11: 2000 | H11: =E11/50 -> 40 | I11: Slop | J11: =D11/H11 -> 7200 | K11: =J11*$K$2 -> 8640 | L11: 10000 | N11: =L11-J11 -> 2800 | O11: =H11*N11 -> 112000
A12: cup puding starindo 60ml | B12: dus | C12: Rp | D12: 222000 | E12: 2000 | H12: =E12/50 -> 40 | I12: Slop | J12: =D12/H12 -> 5550 | K12: =J12*$K$2 -> 6660 | L12: 7000 | M12: 8150 | N12: =L12-J12 -> 1450 | O12: =H12*N12 -> 58000
A13: cup puding starindo 90ml | B13: dus | C13: Rp | D13: 222000 | E13: 2000 | H13: =E13/50 -> 40 | I13: Slop | J13: =D13/H13 -> 5550 | K13: =J13*$K$2 -> 6660 | L13: 8000 | M13: 9450 | N13: =L13-J13 -> 2450 | O13: =H13*N13 -> 98000
A14: cup merak 120ml | B14: dus | C14: Rp | D14: 566000 | E14: 2000 | H14: =E14/25 -> 80 | I14: Slop | J14: =D14/H14 -> 7075 | K14: =J14*$K$2 -> 8490 | M14: 14500 | N14: =L14-J14 -> -7075 | O14: =H14*N14 -> -566000
A15: Lid cup Datar | B15: dus | C15: Rp | D15: 200000 | E15: 2000 | H15: =E15/50 -> 40 | I15: Slop | J15: =D15/H15 -> 5000 | K15: =J15*$K$2 -> 6000 | L15: 6000 | M15: 7500 | N15: =L15-J15 -> 1000 | O15: =H15*N15 -> 40000
A16: Lid cup Cembung | B16: dus | C16: Rp | D16: 278000 | E16: 2000 | H16: =E16/50 -> 40 | I16: Slop | J16: =D16/H16 -> 6950 | K16: =J16*$K$2 -> 8340 | L16: 8000 | M16: 8500 | N16: =L16-J16 -> 1050 | O16: =H16*N16 -> 42000
O17: =H17*N17 -> 0
A18: Box Sterofoam | O18: =H18*N18 -> 0
A19: Box 60kg | B19: koli | C19: Rp | D19: 811000 | E19: 15 | O19: =H19*N19 -> 0
A20: Box 75kg | B20: koli | C20: Rp | D20: 612500 | E20: 14 | O20: =H20*N20 -> 0
A21: Box 35kg | B21: koli | C21: Rp | D21: 982000 | E21: 33 | O21: =H21*N21 -> 0
A22: Box 30kg | B22: koli | C22: Rp | D22: 750000 | E22: 30 | O22: =H22*N22 -> 0
A23: Box 10kg | B23: koli | C23: Rp | D23: 1210000 | E23: 60 | O23: =H23*N23 -> 0
A24: Box 5kg | B24: koli | C24: Rp | D24: 882000 | E24: 60 | O24: =H24*N24 -> 0
A25: Box 2kg | B25: koli | C25: Rp | D25: 752000 | E25: 60 | O25: =H25*N25 -> 0
A26: Box wawan kecil | B26: Pcs | C26: Rp | D26: 25000 | E26: 1 | O26: =H26*N26 -> 0
A27: Box wawan besar | B27: Pcs | C27: Rp | D27: 27500 | E27: 1 | O27: =H27*N27 -> 0
A28: Tf 2 | B28: Bal | C28: Rp | D28: 264000 | E28: 10 | O28: =H28*N28 -> 0
A29: Tf 3 | B29: Bal | C29: Rp | D29: 370000 | E29: 10 | O29: =H29*N29 -> 0
A30: Tf burger | B30: slop | C30: Rp | D30: 45000 | E30: 1 | O30: =H30*N30 -> 0
... A37: Tgp 7 | B37: Bal | C37: Rp | D37: 46000 | E37: 1 | O37: =H37*N37 -> 0
O38: =H38*N38 -> 0
A39: Tali Rafia | O39: =H39*N39 -> 0
A40: Rafia baja 1kg hitam | B40: Bal | C40: Rp | D40: 180000 | E40: 10 | I40: Pack | O40: =H40*N40 -> 0
A41: Rafia baja 1/2kg Hitam | B41: Bal | C41: Rp | D41: 105000 | E41: 10 | O41: =H41*N41 -> 0
A42: Rafia baja 1/4kg Hitam | B42: Bal | C42: Rp | D42: 55000 | E42: 10 | H42: 10 | J42: =D42/H42 -> 5500 | K42: =J42*$K$2 -> 6600 | L42: 7000 | N42: =L42-J42 -> 1500 | O42: =H42*N42 -> 15000
A43: Rafia baja 1kg warna | B43: Bal | C43: Rp | D43: 191000 | E43: 10 | O43: =H43*N43 -> 0
A44: Rafia baja 1/2kg Warna | B44: Bal | C44: Rp | D44: 90000 | E44: 10 | O44: =H44*N44 -> 0
A45: Rafia baja 1/4kg warna | B45: Bal | C45: Rp | D45: 60000 | E45: 10 | O45: =H45*N45 -> 0
A46: rafia baja 1kg natural | B46: Bal | C46: Rp | D46: 180000 | E46: 10 | O46: =H46*N46 -> 0
...

Sheet Purchase
B1: Kemasan_makanan
B2: Date : | C2: 45957 | E2: Total | F2: =SUM(G4:G24) -> 9301000 | G2: Paid|Delivered
B3: No | C3: Item | D3: Qty | F3: Price | G3: Subtotal
B4: 1 | C4: Starindo 14 | D4: 1 | E4: =VLOOKUP(C4,Pricing!$A$2:$D$147,2,FALSE) -> dus | F4: =VLOOKUP(C4,Pricing!$A$2:$D$147,4,FALSE) -> 427000 | G4: =D4*F4 -> 427000
B5: 2 | C5: Starindo 16 | D5: 1 | E5: =VLOOKUP(C5,Pricing!$A$2:$D$147,2,FALSE) -> dus | F5: =VLOOKUP(C5,Pricing!$A$2:$D$147,4,FALSE) -> 427000 | G5: =D5*F5 -> 427000
B6: 3 | C6: Cup Euro motif | D6: 1 | E6: =VLOOKUP(C6,Pricing!$A$2:$D$147,2,FALSE) -> dus | F6: =VLOOKUP(C6,Pricing!$A$2:$D$147,4,FALSE) -> 288000 | G6: =D6*F6 -> 288000
B7: 4 | C7: Rafia baja 1/4kg Hitam | D7: 1 | E7: =VLOOKUP(C7,Pricing!$A$2:$D$147,2,FALSE) -> Bal | F7: =VLOOKUP(C7,Pricing!$A$2:$D$147,4,FALSE) -> 55000 | G7: =D7*F7 -> 55000
B8: 5 | C8: Kertas nasi Gajah | D8: 1 | E8: =VLOOKUP(C8,Pricing!$A$2:$D$147,2,FALSE) -> Karung | F8: =VLOOKUP(C8,Pricing!$A$2:$D$147,4,FALSE) -> 618500 | G8: =D8*F8 -> 618500
B9: 6 | C9: Kertas nasi bulat wp | D9: 5 | E9: =VLOOKUP(C9,Pricing!$A$2:$D$147,2,FALSE) -> ikat | F9: =VLOOKUP(C9,Pricing!$A$2:$D$147,4,FALSE) -> 134000 | G9: =D9*F9 -> 670000
B10: 7 | C10: Hiba Rec 500 | D10: 1 | E10: =VLOOKUP(C10,Pricing!$A$2:$D$147,2,FALSE) -> dus | F10: =VLOOKUP(C10,Pricing!$A$2:$D$147,4,FALSE) -> 426000 | G10: =D10*F10 -> 426000
B11: 8 | C11: Hiba Rec 650 | D11: 1 | E11: =VLOOKUP(C11,Pricing!$A$2:$D$147,2,FALSE) -> dus | F11: =VLOOKUP(C11,Pricing!$A$2:$D$147,4,FALSE) -> 448000 | G11: =D11*F11 -> 448000
B12: 9 | C12: Hiba Rec 750 | D12: 1 | E12: =VLOOKUP(C12,Pricing!$A$2:$D$147,2,FALSE) -> dus | F12: =VLOOKUP(C12,Pricing!$A$2:$D$147,4,FALSE) -> 492000 | G12: =D12*F12 -> 492000
B13: 10 | C13: Hiba Sq 2000 | D13: 1 | E13: =VLOOKUP(C13,Pricing!$A$2:$D$147,2,FALSE) -> dus | F13: =VLOOKUP(C13,Pricing!$A$2:$D$147,4,FALSE) -> 390500 | G13: =D13*F13 -> 390500
B14: 11 | C14: 100x120 Hitam | D14: 1 | E14: =VLOOKUP(C14,Pricing!$A$2:$D$147,2,FALSE) -> ikat | F14: =VLOOKUP(C14,Pricing!$A$2:$D$147,4,FALSE) -> 150000 | G14: =D14*F14 -> 150000
B15: 12 | C15: sendok ecosend putih | D15: 1 | E15: =VLOOKUP(C15,Pricing!$A$2:$D$147,2,FALSE) -> 0 | F15: =VLOOKUP(C15,Pricing!$A$2:$D$147,4,FALSE) -> 180000 | G15: =D15*F15 -> 180000
... B23: 20 | C23: kantong gelas minuman single | D23: 3 | E23: =VLOOKUP(C23,Pricing!$A$2:$D$147,2,FALSE) -> ikat | F23: =VLOOKUP(C23,Pricing!$A$2:$D$147,4,FALSE) -> 40000 | G23: =D23*F23 -> 120000
B24: 21 | C24: kantong gelas minuman double | D24: 3 | E24: =VLOOKUP(C24,Pricing!$A$2:$D$147,2,FALSE) -> ikat | F24: =VLOOKUP(C24,Pricing!$A$2:$D$147,4,FALSE) -> 45000 | G24: =D24*F24 -> 135000 | H24: =F6+F10+F13+F9 -> 1238500
B26: Kemasan_makanan
B27: Date : | C27: 46038 | E27: Total | F27: =SUM(G29:G53) -> 3138750
B28: No | C28: Item | D28: Qty | F28: Price | G28: Subtotal | H28: Notes
B29: 1 | C29: Rajawali 1/4kg | D29: 1 | E29: =VLOOKUP(C29,Pricing!$A$2:$D$281,2,FALSE) -> bal | F29: =VLOOKUP(C29,Pricing!$A$2:$D$281,4,FALSE) -> 48500 | G29: =D29*F29 -> 48500
B30: 2 | C30: Rajawali 1/2kg | D30: 1 | E30: =VLOOKUP(C30,Pricing!$A$2:$D$281,2,FALSE) -> bal | F30: =VLOOKUP(C30,Pricing!$A$2:$D$281,4,FALSE) -> 77000 | G30: =D30*F30 -> 77000
B31: 3 | C31: Rajawali 1kg | D31: 1 | E31: =VLOOKUP(C31,Pricing!$A$2:$D$281,2,FALSE) -> bal | F31: =VLOOKUP(C31,Pricing!$A$2:$D$281,4,FALSE) -> 105000 | G31: =D31*F31 -> 105000
B32: 4 | C32: Rajawali 1 1/2kg | D32: 1 | E32: =VLOOKUP(C32,Pricing!$A$2:$D$281,2,FALSE) -> bal | F32: =VLOOKUP(C32,Pricing!$A$2:$D$281,4,FALSE) -> 125000 | G32: =D32*F32 -> 125000
B33: 5 | C33: Rajawali 2kg | D33: 1 | E33: =VLOOKUP(C33,Pricing!$A$2:$D$281,2,FALSE) -> bal | F33: =VLOOKUP(C33,Pricing!$A$2:$D$281,4,FALSE) -> 171000 | G33: =D33*F33 -> 171000
B34: 6 | C34: 02x35 7kg | D34: 0.5 | E34: =VLOOKUP(C34,Pricing!$A$2:$D$281,2,FALSE) -> karung | F34: =VLOOKUP(C34,Pricing!$A$2:$D$281,4,FALSE) -> 1674500 | G34: =D34*F34 -> 837250 | H34: Plastik Laundry
B35: 7 | C35: 02x50 15kg | D35: 2 | E35: =VLOOKUP(C35,Pricing!$A$2:$D$281,2,FALSE) -> ikat | F35: =VLOOKUP(C35,Pricing!$A$2:$D$281,4,FALSE) -> 195000 | G35: =D35*F35 -> 390000
B36: 8 | C36: 02x60 20kg | D36: 2 | E36: =VLOOKUP(C36,Pricing!$A$2:$D$281,2,FALSE) -> ikat | F36: =VLOOKUP(C36,Pricing!$A$2:$D$281,4,FALSE) -> 275000 | G36: =D36*F36 -> 550000
B37: 9 | C37: 6x6 | D37: 5 | E37: =VLOOKUP(C37,Pricing!$A$2:$D$281,2,FALSE) -> bal | F37: =VLOOKUP(C37,Pricing!$A$2:$D$281,4,FALSE) -> 17000 | G37: =D37*F37 -> 85000 | H37: Plastik OPP Lem
B38: 10 | C38: 7x7 | D38: 5 | E38: =VLOOKUP(C38,Pricing!$A$2:$D$281,2,FALSE) -> bal | F38: =VLOOKUP(C38,Pricing!$A$2:$D$281,4,FALSE) -> 20000 | G38: =D38*F38 -> 100000
B39: 11 | C39: 8x10 | D39: 5 | E39: =VLOOKUP(C39,Pricing!$A$2:$D$281,2,FALSE) -> bal | F39: =VLOOKUP(C39,Pricing!$A$2:$D$281,4,FALSE) -> 30000 | G39: =D39*F39 -> 150000
B40: 12 | C40: 9x9 | D40: 2 | E40: =VLOOKUP(C40,Pricing!$A$2:$D$281,2,FALSE) -> bal | F40: =VLOOKUP(C40,Pricing!$A$2:$D$281,4,FALSE) -> 30000 | G40: =D40*F40 -> 60000
B41: 13 | C41: 10x15 | D41: 2 | E41: =VLOOKUP(C41,Pricing!$A$2:$D$281,2,FALSE) -> bal | F41: =VLOOKUP(C41,Pricing!$A$2:$D$281,4,FALSE) -> 85000 | G41: =D41*F41 -> 170000
B42: 14 | C42: 11x11 | D42: 2 | E42: =VLOOKUP(C42,Pricing!$A$2:$D$281,2,FALSE) -> bal | F42: =VLOOKUP(C42,Pricing!$A$2:$D$281,4,FALSE) -> 43000 | G42: =D42*F42 -> 86000
B43: 15 | C43: 12x12 | D43: 2 | E43: =VLOOKUP(C43,Pricing!$A$2:$D$281,2,FALSE) -> bal | F43: =VLOOKUP(C43,Pricing!$A$2:$D$281,4,FALSE) -> 42000 | G43: =D43*F43 -> 84000
B44: 16 | C44: 13x13 | D44: 2 | E44: =VLOOKUP(C44,Pricing!$A$2:$D$281,2,FALSE) -> bal | F44: =VLOOKUP(C44,Pricing!$A$2:$D$281,4,FALSE) -> 50000 | G44: =D44*F44 -> 100000
L93: 14000
L94: 16000
L95: 19000
L96: 20000
...

Sheet Pricelist
A1: Pricelist
A3: No | B3: Item | C3: Harga Satuan | D3: Harga per pack | E3: Notes
A4: 1 | B4: Starindo 14 | C4: none | D4: =VLOOKUP(B4,Pricing!$A$3:$O$180,12,FALSE) -> 11000 | E4: 50 | F4: pcs per slop
A5: 2 | B5: Starindo 16 | C5: none | D5: =VLOOKUP(B5,Pricing!$A$3:$O$180,12,FALSE) -> 11000 | E5: 50 | F5: pcs per slop
A6: 3 | B6: Cup Euro motif | C6: none | D6: =VLOOKUP(B6,Pricing!$A$3:$O$180,12,FALSE) -> 10000 | E6: 50 | F6: pcs per slop
A7: 4 | B7: Rafia baja 1/4kg Hitam | C7: none | D7: =VLOOKUP(B7,Pricing!$A$3:$O$180,12,FALSE) -> 7000
A8: 5 | B8: Kertas nasi Gajah | C8: none | D8: =VLOOKUP(B8,Pricing!$A$3:$O$180,12,FALSE) -> 30000 | E8: 5 | F8: bks per ikat
A9: 6 | B9: Kertas nasi bulat wp | C9: none | D9: =VLOOKUP(B9,Pricing!$A$3:$O$180,12,FALSE) -> 30000 | E9: 5 | F9: bks per ikat
A10: 7 | B10: Hiba Rec 500 | C10: 1500 | D10: =VLOOKUP(B10,Pricing!$A$3:$O$180,12,FALSE) -> 25000 | E10: 25 | F10: pcs per pack
A11: 8 | B11: Hiba Rec 650 | C11: 1500 | D11: =VLOOKUP(B11,Pricing!$A$3:$O$180,12,FALSE) -> 26000 | E11: 25 | F11: pcs per pack
A12: 9 | B12: Hiba Rec 750 | C12: 1500 | D12: =VLOOKUP(B12,Pricing!$A$3:$O$180,12,FALSE) -> 28000 | E12: 25 | F12: pcs per pack
A13: 10 | B13: Hiba Sq 2000 | C13: 3000 | D13: =VLOOKUP(B13,Pricing!$A$3:$O$180,12,FALSE) -> 70000 | E13: 25 | F13: pcs per pack
A14: 11 | B14: 100x120 Hitam | C14: none | D14: =VLOOKUP(B14,Pricing!$A$3:$O$180,12,FALSE) -> 20000 | E14: 10 | F14: pcs per pack
A15: 12 | B15: sendok ecosend putih | C15: none | D15: =VLOOKUP(B15,Pricing!$A$3:$O$180,12,FALSE) -> 11000 | E15: 100 | F15: pcs per pack
A16: 13 | B16: garpu putih | C16: none | D16: =VLOOKUP(B16,Pricing!$A$3:$O$180,12,FALSE) -> 13000 | E16: 100 | F16: pcs per pack
A17: 14 | B17: sedotan tusuk cover plastik | C17: none | D17: =VLOOKUP(B17,Pricing!$A$3:$O$180,12,FALSE) -> 27000 | E17: 500 | F17: pcs per pack
A18: 15 | B18: Jolly Facial 250's | C18: 9000 | D18: 35000 | E18: 4 | F18: pcs per pack
A19: 16 | B19: Kresek kilat 40 Merah | C19: none | D19: =VLOOKUP(B19,Pricing!$A$3:$O$180,12,FALSE) -> 32000 | E19: 50 | F19: pcs per pack
A20: 17 | B20: Kresek 32 Lorek | C20: none | D20: =VLOOKUP(B20,Pricing!$A$3:$O$180,12,FALSE) -> 18000 | E20: 50 | F20: pcs per pack
A21: 18 | B21: Kresek kilat 28 putih | C21: none | D21: =VLOOKUP(B21,Pricing!$A$3:$O$180,12,FALSE) -> 13000 | E21: 50 | F21: pcs per pack
A22: 19 | B22: kresek los warna 15 | C22: 16000 | D22: 15000 | E22: 2 | F22: pcs minimal
A23: 20 | B23: kantong gelas minuman single | C23: none | D23: =VLOOKUP(B23,Pricing!$A$3:$O$180,12,FALSE) -> 5000
A24: 21 | B24: kantong gelas minuman double | C24: none | D24: =VLOOKUP(B24,Pricing!$A$3:$O$180,12,FALSE) -> 6000

Sheet Accounting
A1: Total | B1: =SUM(G:G) -> 12669500
A2: No | B2: Item | C2: Stock In | D2: Harga Pokok | E2: Harga TOKO | F2: Margin | G2: Subtotal Margin | H2: HARGA SHOPEE | I2: MARGIN SHOPEE | J2: TOTAL MARGIN SHOPEE | K2: Potongan Ecommerce | L2: Margin Ecommerce
E3: 1.5 | K3: 0.1
A4: 1 | B4: Starindo 14 | C4: =VLOOKUP(B4,Pricing!$A$1:$O$281,8,FALSE) -> 40 | D4: =VLOOKUP(B4,Pricing!$A$1:$O$281,10,FALSE) -> 10675 | E4: 15000 | F4: =E4-D4 -> 4325 | G4: =C4*F4 -> 173000 | H4: 16000 | I4: =H4-D4 -> 5325 | J4: =C4*I4 -> 213000 | K4: =H4*$K$3 -> 1600 | L4: =J4-(J4*$K$3) -> 191700
A5: 2 | B5: Starindo 16 | C5: =VLOOKUP(B5,Pricing!$A$1:$O$281,8,FALSE) -> 40 | D5: =VLOOKUP(B5,Pricing!$A$1:$O$281,10,FALSE) -> 10675 | E5: 15000 | F5: =E5-D5 -> 4325 | G5: =C5*F5 -> 173000 | H5: 16000 | I5: =H5-D5 -> 5325 | J5: =C5*I5 -> 213000 | K5: =H5*$K$3 -> 1600 | L5: =J5-(K5*C5) -> 149000
A6: 3 | B6: Cup Euro motif | C6: =VLOOKUP(B6,Pricing!$A$1:$O$281,8,FALSE) -> 40 | D6: =VLOOKUP(B6,Pricing!$A$1:$O$281,10,FALSE) -> 7200 | E6: 11000 | F6: =E6-D6 -> 3800 | G6: =C6*F6 -> 152000 | H6: 13000 | I6: =H6-D6 -> 5800 | J6: =C6*I6 -> 232000 | K6: =H6*$K$3 -> 1300 | L6: =J6-(K6*C6) -> 180000
A7: 4 | B7: Rafia baja 1/4kg Hitam | C7: =VLOOKUP(B7,Pricing!$A$1:$O$281,8,FALSE) -> 10 | D7: =VLOOKUP(B7,Pricing!$A$1:$O$281,10,FALSE) -> 5500 | E7: 7000 | F7: =E7-D7 -> 1500 | G7: =C7*F7 -> 15000 | H7: 7000 | I7: =H7-D7 -> 1500 | J7: =C7*I7 -> 15000 | K7: =H7*$K$3 -> 700 | L7: =J7-(K7*C7) -> 8000
A8: 5 | B8: Kertas nasi Gajah | C8: =VLOOKUP(B8,Pricing!$A$1:$O$281,8,FALSE) -> 25 | D8: =VLOOKUP(B8,Pricing!$A$1:$O$281,10,FALSE) -> 24740 | E8: 35000 | F8: =E8-D8 -> 10260 | G8: =C8*F8 -> 256500 | H8: 34900 | I8: =H8-D8 -> 10160 | J8: =C8*I8 -> 254000 | K8: =H8*$K$3 -> 3490 | L8: =J8-(K8*C8) -> 166750
A9: 6 | B9: Kertas nasi bulat wp | C9: =VLOOKUP(B9,Pricing!$A$1:$O$281,8,FALSE) -> 25 | D9: =VLOOKUP(B9,Pricing!$A$1:$O$281,10,FALSE) -> 5360 | E9: 15000 | F9: =E9-D9 -> 9640 | G9: =C9*F9 -> 241000 | H9: 14900 | I9: =H9-D9 -> 9540 | J9: =C9*I9 -> 238500 | K9: =H9*$K$3 -> 1490 | L9: =J9-(K9*C9) -> 201250
A10: 7 | B10: Hiba Rec 500 | C10: =VLOOKUP(B10,Pricing!$A$1:$O$281,8,FALSE) -> 20 | D10: =VLOOKUP(B10,Pricing!$A$1:$O$281,10,FALSE) -> 21300 | E10: 35000 | F10: =E10-D10 -> 13700 | G10: =C10*F10 -> 274000 | H10: 34900 | I10: =H10-D10 -> 13600 | J10: =C10*I10 -> 272000 | K10: =H10*$K$3 -> 3490 | L10: =J10-(K10*C10) -> 202200
A11: 8 | B11: Hiba Rec 650 | C11: =VLOOKUP(B11,Pricing!$A$1:$O$281,8,FALSE) -> 20 | D11: =VLOOKUP(B11,Pricing!$A$1:$O$281,10,FALSE) -> 22400 | E11: 38000 | F11: =E11-D11 -> 15600 | G11: =C11*F11 -> 312000 | H11: 38000 | I11: =H11-D11 -> 15600 | J11: =C11*I11 -> 312000 | K11: =H11*$K$3 -> 3800 | L11: =J11-(K11*C11) -> 236000
A12: 9 | B12: Hiba Rec 750 | C12: =VLOOKUP(B12,Pricing!$A$1:$O$281,8,FALSE) -> 20 | D12: =VLOOKUP(B12,Pricing!$A$1:$O$281,10,FALSE) -> 24600 | E12: 42000 | F12: =E12-D12 -> 17400 | G12: =C12*F12 -> 348000 | H12: 41900 | I12: =H12-D12 -> 17300 | J12: =C12*I12 -> 346000 | K12: =H12*$K$3 -> 4190 | L12: =J12-(K12*C12) -> 262200
A13: 10 | B13: Hiba Sq 2000 | C13: =VLOOKUP(B13,Pricing!$A$1:$O$281,8,FALSE) -> 6 | D13: =VLOOKUP(B13,Pricing!$A$1:$O$281,10,FALSE) -> 65083.333 | E13: 80000 | F13: =E13-D13 -> 14916.667 | G13: =C13*F13 -> 89500 | H13: 80000 | I13: =H13-D13 -> 14916.667 | J13: =C13*I13 -> 89500 | K13: =H13*$K$3 -> 8000 | L13: =J13-(K13*C13) -> 41500
A14: 11 | B14: 100x120 Hitam | C14: =VLOOKUP(B14,Pricing!$A$1:$O$281,8,FALSE) -> 10 | D14: =VLOOKUP(B14,Pricing!$A$1:$O$281,10,FALSE) -> 15000 | E14: 22000 | F14: =E14-D14 -> 7000 | G14: =C14*F14 -> 70000 | H14: 22000 | I14: =H14-D14 -> 7000 | J14: =C14*I14 -> 70000 | K14: =H14*$K$3 -> 2200 | L14: =J14-(K14*C14) -> 48000
A15: 12 | B15: sendok ecosend putih | C15: =VLOOKUP(B15,Pricing!$A$1:$O$281,8,FALSE) -> 20 | D15: =VLOOKUP(B15,Pricing!$A$1:$O$281,10,FALSE) -> 9000 | E15: 15000 | F15: =E15-D15 -> 6000 | G15: =C15*F15 -> 120000 | H15: 15000 | I15: =H15-D15 -> 6000 | J15: =C15*I15 -> 120000 | K15: =H15*$K$3 -> 1500 | L15: =J15-(K15*C15) -> 90000
A16: 13 | B16: garpu putih | C16: =VLOOKUP(B16,Pricing!$A$1:$O$281,8,FALSE) -> 30 | D16: =VLOOKUP(B16,Pricing!$A$1:$O$281,10,FALSE) -> 10500 | E16: 15000 | F16: =E16-D16 -> 4500 | G16: =C16*F16 -> 135000 | H16: 14900 | I16: =H16-D16 -> 4400 | J16: =C16*I16 -> 132000 | K16: =H16*$K$3 -> 1490 | L16: =J16-(K16*C16) -> 87300
... A22: 19 | B22: kresek los warna 15 | C22: =VLOOKUP(B22,Pricing!$A$1:$O$281,8,FALSE) -> 36 | D22: =VLOOKUP(B22,Pricing!$A$1:$O$281,10,FALSE) -> 14722.222 | E22: 20000 | F22: =E22-D22 -> 5277.7778 | G22: =C22*F22 -> 190000 | H22: 19900 | I22: =H22-D22 -> 5177.7778 | J22: =C22*I22 -> 186400 | K22: =H22*$K$3 -> 1990 | L22: =J22-(K22*C22) -> 114760
A23: 20 | B23: kantong gelas minuman single | C23: =VLOOKUP(B23,Pricing!$A$1:$O$281,8,FALSE) -> 30 | D23: =VLOOKUP(B23,Pricing!$A$1:$O$281,10,FALSE) -> 1333.3333 | E23: 5000 | F23: =E23-D23 -> 3666.6667 | G23: =C23*F23 -> 110000 | I23: =H23-D23 -> -1333.3333 | J23: =C23*I23 -> -40000 | K23: =H23*$K$3 -> 0 | L23: =J23-(K23*C23) -> -40000
A24: 21 | B24: kantong gelas minuman double | C24: =VLOOKUP(B24,Pricing!$A$1:$O$281,8,FALSE) -> 30 | D24: =VLOOKUP(B24,Pricing!$A$1:$O$281,10,FALSE) -> 1500 | E24: 6000 | F24: =E24-D24 -> 4500 | G24: =C24*F24 -> 135000 | I24: =H24-D24 -> -1500 | J24: =C24*I24 -> -45000 | K24: =H24*$K$3 -> 0 | L24: =J24-(K24*C24) -> -45000
A25: 22 | B25: Rajawali 1/4kg | C25: =VLOOKUP(B25,Pricing!$A$1:$O$281,8,FALSE) -> 10 | D25: =VLOOKUP(B25,Pricing!$A$1:$O$281,10,FALSE) -> 4850 | E25: 9000 | F25: =E25-D25 -> 4150 | G25: =C25*F25 -> 41500 | H25: 9000 | I25: =H25-D25 -> 4150 | J25: =C25*I25 -> 41500 | K25: =H25*$K$3 -> 900 | L25: =J25-(K25*C25) -> 32500
A26: 23 | B26: Rajawali 1/2kg | C26: =VLOOKUP(B26,Pricing!$A$1:$O$281,8,FALSE) -> 10 | D26: =VLOOKUP(B26,Pricing!$A$1:$O$281,10,FALSE) -> 7700 | E26: 15000 | F26: =E26-D26 -> 7300 | G26: =C26*F26 -> 73000 | H26: 15000 | I26: =H26-D26 -> 7300 | J26: =C26*I26 -> 73000 | K26: =H26*$K$3 -> 1500 | L26: =J26-(K26*C26) -> 58000
A27: 24 | B27: Rajawali 1kg | C27: =VLOOKUP(B27,Pricing!$A$1:$O$281,8,FALSE) -> 10 | D27: =VLOOKUP(B27,Pricing!$A$1:$O$281,10,FALSE) -> 10500 | E27: 21000 | F27: =E27-D27 -> 10500 | G27: =C27*F27 -> 105000 | H27: 21000 | I27: =H27-D27 -> 10500 | J27: =C27*I27 -> 105000 | K27: =H27*$K$3 -> 2100 | L27: =J27-(K27*C27) -> 84000
A28: 25 | B28: Rajawali 1 1/2kg | C28: =VLOOKUP(B28,Pricing!$A$1:$O$281,8,FALSE) -> 10 | D28: =VLOOKUP(B28,Pricing!$A$1:$O$281,10,FALSE) -> 12500 | E28: 25000 | F28: =E28-D28 -> 12500 | G28: =C28*F28 -> 125000 | H28: 25000 | I28: =H28-D28 -> 12500 | J28: =C28*I28 -> 125000 | K28: =H28*$K$3 -> 2500 | L28: =J28-(K28*C28) -> 100000
A29: 26 | B29: Rajawali 2kg | C29: =VLOOKUP(B29,Pricing!$A$1:$O$281,8,FALSE) -> 10 | D29: =VLOOKUP(B29,Pricing!$A$1:$O$281,10,FALSE) -> 17100 | E29: 30000 | F29: =E29-D29 -> 12900 | G29: =C29*F29 -> 129000 | H29: 30000 | I29: =H29-D29 -> 12900 | J29: =C29*I29 -> 129000 | K29: =H29*$K$3 -> 3000 | L29: =J29-(K29*C29) -> 99000
A30: 27 | B30: 02x35 7kg | C30: =VLOOKUP(B30,Pricing!$A$1:$O$281,8,FALSE)/2 -> 34.5 | D30: =VLOOKUP(B30,Pricing!$A$1:$O$281,10,FALSE) -> 24268.116 | E30: 40000 | F30: =E30-D30 -> 15731.884 | G30: =C30*F30 -> 542750 | I30: =H30-D30 -> -24268.116 | J30: =C30*I30 -> -837250 | K30: =H30*$K$3 -> 0 | L30: =J30-(K30*C30) -> -837250
A31: 28 | B31: 02x50 15kg | C31: =10*VLOOKUP(B31,Pricing!$A$1:$O$281,8,FALSE) -> 50 | D31: =VLOOKUP(B31,Pricing!$A$1:$O$281,10,FALSE) -> 39000 | E31: 65000 | F31: =E31-D31 -> 26000 | G31: =C31*F31 -> 1300000 | I31: =H31-D31 -> -39000 | J31: =C31*I31 -> -1950000 | K31: =H31*$K$3 -> 0 | L31: =J31-(K31*C31) -> -1950000
A32: 29 | B32: 02x60 20kg | C32: =10*VLOOKUP(B32,Pricing!$A$1:$O$281,8,FALSE) -> 50 | D32: =VLOOKUP(B32,Pricing!$A$1:$O$281,10,FALSE) -> 55000 | E32: 85000 | F32: =E32-D32 -> 30000 | G32: =C32*F32 -> 1500000 | I32: =H32-D32 -> -55000 | J32: =C32*I32 -> -2750000 | K32: =H32*$K$3 -> 0 | L32: =J32-(K32*C32) -> -2750000
A33: 30 | B33: 6x6 | C33: =5*VLOOKUP(B33,Pricing!$A$1:$O$281,8,FALSE) -> 50 | D33: =VLOOKUP(B33,Pricing!$A$1:$O$281,10,FALSE) -> 1700 | E33: 2500 | F33: =E33-D33 -> 800 | G33: =C33*F33 -> 40000 | I33: =H33-D33 -> -1700 | J33: =C33*I33 -> -85000 | K33: =H33*$K$3 -> 0 | L33: =J33-(K33*C33) -> -85000
A34: 31 | B34: 7x7 | C34: =5*VLOOKUP(B34,Pricing!$A$1:$O$281,8,FALSE) -> 50 | D34: =VLOOKUP(B34,Pricing!$A$1:$O$281,10,FALSE) -> 2000 | E34: 3000 | F34: =E34-D34 -> 1000 | G34: =C34*F34 -> 50000 | I34: =H34-D34 -> -2000 | J34: =C34*I34 -> -100000 | K34: =H34*$K$3 -> 0 | L34: =J34-(K34*C34) -> -100000
A35: 32 | B35: 8x10 | C35: =5*VLOOKUP(B35,Pricing!$A$1:$O$281,8,FALSE) -> 50 | D35: =VLOOKUP(B35,Pricing!$A$1:$O$281,10,FALSE) -> 3000 | E35: =D35*$E$3 -> 4500 | F35: =E35-D35 -> 1500 | G35: =C35*F35 -> 75000 | I35: =H35-D35 -> -3000 | J35: =C35*I35 -> -150000 | K35: =H35*$K$3 -> 0 | L35: =J35-(K35*C35) -> -150000
A36: 33 | B36: 9x9 | C36: =2*VLOOKUP(B36,Pricing!$A$1:$O$281,8,FALSE) -> 20 | D36: =VLOOKUP(B36,Pricing!$A$1:$O$281,10,FALSE) -> 3000 | E36: =D36*$E$3 -> 4500 | F36: =E36-D36 -> 1500 | G36: =C36*F36 -> 30000 | I36: =H36-D36 -> -3000 | J36: =C36*I36 -> -60000 | K36: =H36*$K$3 -> 0 | L36: =J36-(K36*C36) -> -60000
A37: 34 | B37: 10x15 | C37: =2*VLOOKUP(B37,Pricing!$A$1:$O$281,8,FALSE) -> 20 | D37: =VLOOKUP(B37,Pricing!$A$1:$O$281,10,FALSE) -> 8500 | E37: 12500 | F37: =E37-D37 -> 4000 | G37: =C37*F37 -> 80000 | I37: =H37-D37 -> -8500 | J37: =C37*I37 -> -170000 | K37: =H37*$K$3 -> 0 | L37: =J37-(K37*C37) -> -170000
A38: 35 | B38: 11x11 | C38: =2*VLOOKUP(B38,Pricing!$A$1:$O$281,8,FALSE) -> 20 | D38: =VLOOKUP(B38,Pricing!$A$1:$O$281,10,FALSE) -> 4300 | E38: 6500 | F38: =E38-D38 -> 2200 | G38: =C38*F38 -> 44000 | I38: =H38-D38 -> -4300 | J38: =C38*I38 -> -86000 | K38: =H38*$K$3 -> 0 | L38: =J38-(K38*C38) -> -86000
A39: 36 | B39: 12x12 | C39: =2*VLOOKUP(B39,Pricing!$A$1:$O$281,8,FALSE) -> 20 | D39: =VLOOKUP(B39,Pricing!$A$1:$O$281,10,FALSE) -> 4200 | E39: 6500 | F39: =E39-D39 -> 2300 | G39: =C39*F39 -> 46000 | I39: =H39-D39 -> -4200 | J39: =C39*I39 -> -84000 | K39: =H39*$K$3 -> 0 | L39: =J39-(K39*C39) -> -84000
A40: 37 | B40: 13x13 | C40: =2*VLOOKUP(B40,Pricing!$A$1:$O$281,8,FALSE) -> 20 | D40: =VLOOKUP(B40,Pricing!$A$1:$O$281,10,FALSE) -> 5000 | E40: =D40*$E$3 -> 7500 | F40: =E40-D40 -> 2500 | G40: =C40*F40 -> 50000 | I40: =H40-D40 -> -5000 | J40: =C40*I40 -> -100000 | K40: =H40*$K$3 -> 0 | L40: =J40-(K40*C40) -> -100000
E41: =D41*$E$3 -> 0 | H41: =D41*$H$3 -> 0 | K41: =H41*$K$3 -> 0 | L41: =J41-(K41*C41) -> 0
A42: 38 | B42: Plastik Sampah Hitam 90X100 | C42: 80 | D42: =607200/C42 -> 7590 | E42: 13000 | F42: =E42-D42 -> 5410 | G42: =F42*C42 -> 432800 | H42: 11000 | I42: =D42*$I$3 -> 0 | J42: 12500 | K42: =H42*$K$3 -> 1100 | L42: =J42-(K42*C42) -> -75500
A43: 39 | B43: Plastik Sampah Hitam 60X80 | C43: 140 | D43: =571550/C43 -> 4082.5 | E43: 8000 | F43: =E43-D43 -> 3917.5 | G43: =C43*F43 -> 548450 | H43: 6500 | I43: =D43*$I$3 -> 0 | J43: 8000 | K43: =H43*$K$3 -> 650 | L43: =J43-(K43*C43) -> -83000
A44: 40 | B44: Paper Cup 8 Oz | C44: =1000/50 -> 20 | D44: =175000/C44 -> 8750 | E44: 13000 | F44: =E44-D44 -> 4250 | G44: =C44*F44 -> 85000 | I44: =D44*$I$3 -> 0 | J44: 12500 | K44: =H44*$K$3 -> 0 | L44: =J44-(K44*C44) -> 12500
A45: 41 | B45: Sendok Jerapah Putih | C45: =2000/100 -> 20 | D45: =170000/C45 -> 8500 | E45: 12500 | F45: =E45-D45 -> 4000 | G45: =C45*F45 -> 80000 | I45: =D45*$I$3 -> 0 | J45: 12500 | K45: =H45*$K$3 -> 0 | L45: =J45-(K45*C45) -> 12500
...
